<?xml version="1.0"?>
<robot name="cobot" xmlns:xacro="http://www.ros.org/wiki/xacro">

    <xacro:property name="models" value="$(find my_cobot)/models/" />

    <material name="blue">
        <color rgba="0 0 0.8 1"/>
    </material>
    <material name="red">
        <color rgba="0.8 0 0 1"/>
    </material>
    <material name="green">
        <color rgba="0 0.8 0 1"/>
    </material>
    <material name="grey">
        <color rgba="0.75 0.75 0.75 1"/>
    </material>
    <material name="white">
        <color rgba="1.0 1.0 1.0 1"/>
    </material>
    <material name="black">
        <color rgba="0 0 0 1"/>
    </material>

	<!-- * * * Link Definitions * * * -->
    <link name="L1_link">
        <collision>
            <origin rpy="0.0 0 0" xyz="0 0 0.03057"/>
            <geometry>
                <cylinder radius="0.045" length="0.06114"/>
            </geometry>
        </collision>

        <visual>
            <origin rpy="0.0 0 0" xyz="0 0 0"/>
            <geometry>
                <cylinder radius="0.045" length="0.06114"/>
                <!-- <mesh filename="package://my_cobot/models/joint1.dae"/> -->
            </geometry>
            <material name="white"/>
        </visual>
	</link>



    <link name="L2_link">
        <collision>
            <origin rpy="0 0 0" xyz="0 0 0.03057"/>
            <geometry>
                <cylinder radius="0.0245" length="0.07042"/>
            </geometry>
        </collision>

        <visual>
            <origin rpy="0 0 1.5708" xyz="0 0 0"/>
            <geometry>
                <cylinder radius="0.0245" length="0.07042"/>
                <!-- <mesh filename="package://my_cobot/models/joint2.dae"/> -->
            </geometry>
            <material name="white"/>
        </visual>
	</link>

    <joint name="J1_joint" type="continuous">
    	<parent link="L1_link"/>
    	<child link="L2_link"/>
        <origin xyz="0 0 0.06114" rpy="0 0 0"/>
        <limit effort="0.1" velocity="0.005"/>
        <axis xyz="0 0 1"/>
	</joint>



    <link name="L3_link">
        <collision>
            <origin rpy="0 0 1.5708" xyz="0 0 0.0552"/>
            <geometry>
                <cylinder radius="0.0245" length="0.1104"/>
            </geometry>
        </collision>

        <visual>
            <origin rpy="0 0 1.5708" xyz="0 -0.0245 0"/>
            <geometry>
                <cylinder radius="0.0245" length="0.1104"/>
                <!-- <mesh filename="package://my_cobot/models/joint3.dae"/> -->
            </geometry>
            <material name="white"/>
        </visual>
	</link>

    <joint name="J2_joint" type="revolute">
    	<parent link="L2_link"/>
    	<child link="L3_link"/>
        <origin xyz="0 0.06639 0.07042" rpy="0 0 0"/>
        <limit lower="-2.7925" upper="2.7925" effort="0.1" velocity="0.005"/>
        <axis xyz="0 -1 0"/>
	</joint>



    <link name="L4_link">
        <collision>
            <origin rpy="0 0 -1.5708" xyz="0 0 0.048"/>
            <geometry>
                <cylinder radius="0.0245" length="0.096"/>
            </geometry>
        </collision>

        <visual>
            <origin rpy="0 0 1.5708" xyz="0 0.0245 0"/>
            <geometry>
                <cylinder radius="0.0245" length="0.096"/>
                <!-- <mesh filename="package://my_cobot/models/joint4.dae"/> -->
            </geometry>
            <material name="white"/>
        </visual>
	</link>

    <joint name="J3_joint" type="revolute">
    	<parent link="L3_link"/>
    	<child link="L4_link"/>
        <origin xyz="0 -0.06639 0.1104" rpy="0 0 0"/>
        <limit lower="-2.7925" upper="2.7925" effort="0.1" velocity="0.005"/>
        <axis xyz="0 -1 0"/>
	</joint>



    <link name="L5_link">
        <collision>
            <origin rpy="0 0 -1.5708" xyz="0 0 0"/>
            <geometry>
                <cylinder radius="0.0245" length="0.03659"/>
            </geometry>
        </collision>

        <visual>
            <origin rpy="3.1416 0 0" xyz="0 -0.0245 0"/>
            <geometry>
                <cylinder radius="0.0245" length="0.03659"/>
                <!-- <mesh filename="package://my_cobot/models/joint5.dae"/> -->
            </geometry>
            <material name="white"/>
        </visual>
	</link>

    <joint name="J4_joint" type="continuous">
    	<parent link="L4_link"/>
    	<child link="L5_link"/>
        <origin xyz="0 0.06639 0.096" rpy="0 0 0"/>
        <limit effort="0.1" velocity="0.005"/>
        <axis xyz="0 -1 0"/>
	</joint>



    <link name="L6_link">
        <collision>
            <origin rpy="0 0 -1.5708" xyz="0 0 -0.018295"/>
            <geometry>
                <cylinder radius="0.0245" length="0.03659"/>
            </geometry>
        </collision>

        <visual>
            <origin rpy="0 0 0" xyz="0 0 -0.03655"/>
            <geometry>
                <cylinder radius="0.0245" length="0.03659"/>
                <!-- <mesh filename="package://my_cobot/models/joint6.dae"/> -->
            </geometry>
            <material name="white"/>
        </visual>
	</link>

    <joint name="J5_joint" type="continuous">
    	<parent link="L5_link"/>
    	<child link="L6_link"/>
        <origin xyz="0 0 0.07318" rpy="0 0 0"/>
        <limit effort="0.1" velocity="0.005"/>
        <axis xyz="0 0 1"/>
	</joint>



    <link name="L7_link">
        <collision>
            <origin rpy="-1.5708 0 0" xyz="0 -0.0218 0"/>
            <geometry>
                <cylinder radius="0.0245" length="0.0436"/>
            </geometry>
        </collision>

        <visual>
            <origin rpy="-1.5708 0 0" xyz="0 -0.0218 0"/>
            <geometry>
                <cylinder radius="0.0245" length="0.0436"/>
                <!-- <mesh filename="package://my_cobot/models/joint7.dae"/> -->
            </geometry>
            <material name="white"/>
        </visual>
	</link>

    <joint name="J6_joint" type="continuous">
    	<parent link="L6_link"/>
    	<child link="L7_link"/>
        <origin xyz="0 0.0436 0" rpy="0 0 0"/>
        <limit effort="0.1" velocity="0.005"/>
        <axis xyz="0 -1 0"/>
	</joint>

</robot>